Workbook

Sheet Read Me
A1: MARS: HABITAT: resource balance
A2: Every number the habitat simulation uses is kept here. Change a number, save, and the game picks it up when the data is re-imported (tools/import_balance.py).
A4: Colour key
A5: Blue text: a number you can change.
A6: Black text: worked out by a formula. Don't type over it.
A7: Green text: copied from another sheet.
A8: Yellow fill: the most important levers for difficulty.
A10: Sheets
A11: Settings: crew needs and habitat-wide numbers (mission length, cargo budget, insulation).
A12: Rooms: cargo cost and base power for each 3 x 3 m cell of each room type.
A13: Equipment: every placeable item: cargo, power, what it makes or uses, what it stores. 'Reference qty' is a sensible 6-crew design used by Balance Check.
A14: Sites: what makes each landing site different: sun, temperature, ice, dust storms, cargo bonus.
... A20: Figures are realistic ballparks (mostly NASA ISS life-support planning numbers), simplified for Year 9. They are meant to be tuned for play.

Sheet Settings
A1: Setting | B1: Value | C1: Unit | D1: Notes / real-world basis | E1: Game key (don't change)
A2: Crew size | B2: 6 | C2: people | D2: Mission crew. The student is the commander, one of the six. | E2: crew
A3: Mission length (reference) | B3: 100 | C3: sols | D3: Used by Balance Check for food to bring. Missions set their own length. | E3: mission_sols
A4: Cargo budget | B4: 100000 | C4: kg | D4: Survival starting cargo. Raised to 100,000 on 22 Oct when Earth resupply was switched off: the regolith printer is now how the base grows. Freedom starts with more (below). Missions set their own per-landing payloads. | E4: cargo_budget_kg | F4: 120000
A5: Food the lander brings | B5: 60 | C5: sols | D5: Survival and Freedom: food for the crew when they move in (it does not count against cargo). Missions will let students choose. | E5: start_food_sols
A6: Oxygen breathed | B6: 0.84 | C6: kg/person/sol | D6: NASA Baseline Values and Assumptions Document (BVAD). | E6: o2_per_person
A7: CO2 breathed out | B7: 1 | C7: kg/person/sol | D7: NASA BVAD. | E7: co2_per_person
A8: Water used | B8: 10 | C8: L/person/sol | D8: Drink 2.5, food 1, hygiene 6, toilet 0.5. ISS crews use less; this allows short showers. | E8: water_per_person
A9: Food eaten | B9: 1.8 | C9: kg/person/sol | D9: Packaged food including packaging, about 3,000 kcal. | E9: food_per_person
A10: Body heat given off | B10: 0.1 | C10: kW/person | D10: A resting adult gives off about 100 W. | E10: body_heat_kw
A11: Hull heat loss (U value) | B11: 0.25 | C11: W/m2/C | D11: How fast heat leaks through the hull. Lower = better insulated. The main difficulty lever for cold sites. | E11: hull_u
A12: Hull area per cell | B12: 27 | C12: m2 | D12: Roof + floor + about one outer wall of a 3 x 3 x 2.9 m cell. | E12: hull_area_per_cell
A13: Window heat loss | B13: 6 | C13: x hull | D13: A window loses heat like this many times its area of hull. | E13: window_loss_factor
A14: Window area | B14: 3 | C14: m2 | D14: One hull window band. | E14: window_area
A15: Comfortable temperature | B15: 20 | C15: C | D15: Thermal control aims for this. Comfortable is 18-26 C. | E15: indoor_target_c
A16: Heat pump efficiency | B16: 3 | C16: x | D16: 1 kW of electricity moves about 3 kW of heat (thermal control unit). | E16: heat_pump_cop
... A32: Resupply size (Survival) | B32: 15000 | C32: kg | D32: Cargo each Survival resupply lander brings. | E32: resupply_kg_survival
A33: Resupply interval (Freedom) | B33: 2 | C33: sols | E33: resupply_sols_freedom
A34: Resupply size (Freedom) | B34: 20000 | C34: kg | E34: resupply_kg_freedom
A35: Printer output | B35: 2500 | C35: kg/sol | D35: Mars-made material from one running regolith printer fed by a running intake. Pays for room shells, corridors, partitions, shelving, crates and tables. | E35: print_kg_per_sol
A36: Recycling bonus | B36: 0.25 | C36: fraction | D36: Extra printer output when the base has a plastics recycling hopper (plastic binder). | E36: print_recycle_bonus
A37: Earth resupply landers | B37: 0 | C37: on/off | D37: 1 = resupply landers arrive on launch windows in Survival and Freedom. Switched off (0) on 22 Oct: the regolith printer is the way to grow the base. | E37: resupply_enabled
A38: Storm warning | B38: 10 | C38: hours | D38: How long before a dust storm the forecast warns you. Real orbiters (MRO) photograph the whole planet every sol, so storms are seen coming. | E38: storm_warning_hours

Sheet Rooms
A1: Room type (game id) | B1: Room | C1: Cargo per cell (kg) | D1: Always-on power per cell (kW) | E1: Light power per cell (kW) | F1: Target temperature (C) | G1: Reference cells | H1: Reference cargo (kg) | I1: Notes
A2: living | B2: Living Quarters | C2: 800 | D2: 0.03 | E2: 0.05 | F2: 20 | G2: 9 | H2: =C2*G2 | I2: Every 3 cells give room for 2 crew.
A3: galley | B3: Galley | C3: 800 | D3: 0.03 | E3: 0.05 | F3: 20 | G3: 3 | H3: =C3*G3
A4: hygiene | B4: Hygiene | C4: 800 | D4: 0.03 | E4: 0.05 | F4: 21 | G4: 2 | H4: =C4*G4
A5: medical | B5: Medical Bay | C5: 800 | D5: 0.03 | E5: 0.05 | F5: 21 | G5: 2 | H5: =C5*G5
A6: science | B6: Science Laboratory | C6: 800 | D6: 0.03 | E6: 0.05 | F6: 21 | G6: 4 | H6: =C6*G6
A7: hydroponics | B7: Hydroponics | C7: 800 | D7: 0.03 | E7: 0.05 | F7: 24 | G7: 6 | H7: =C7*G7 | I7: Plants like it warm.
A8: life_support | B8: Life Support | C8: 800 | D8: 0.03 | E8: 0.05 | F8: 18 | G8: 4 | H8: =C8*G8
A9: engineering | B9: Power & Engineering | C9: 800 | D9: 0.03 | E9: 0.05 | F9: 18 | G9: 3 | H9: =C9*G9
A10: storage | B10: Storage | C10: 700 | D10: 0.03 | E10: 0.05 | F10: 12 | G10: 3 | H10: =C10*G10 | I10: Kept cool; less fit-out.
A11: waste_management | B11: Waste Management | C11: 800 | D11: 0.03 | E11: 0.05 | F11: 16 | G11: 2 | H11: =C11*G11
A12: communications | B12: Mission Operations | C12: 800 | D12: 0.03 | E12: 0.05 | F12: 20 | G12: 2 | H12: =C12*G12
A13: corridor | B13: Corridor | C13: 600 | D13: 0.03 | E13: 0.05 | F13: 16 | G13: 4 | H13: =C13*G13 | I13: Lighter, narrower structure.
A14: airlock | B14: Airlock | C14: 1500 | D14: 0.03 | E14: 0.05 | F14: 8 | G14: 2 | H14: =C14*G14 | I14: Pumps, doors and seals make it heavy.
A15: vehicle_bay | B15: Vehicle Bay | C15: 900 | D15: 0.03 | E15: 0.05 | F15: 6 | G15: 0 | H15: =C15*G15 | I15: Large door; kept cold.
A16: Total | G16: =SUM(G2:G15) | H16: =SUM(H2:H15)
A18: Hull window (each) | C18: 150 | I18: Extra cargo for each window. Heat loss is in Settings.
A19: Always-on power is ventilation and controls. Light power counts for 'Room lights on per sol' hours.

Sheet Equipment
A1: Item (game id) | B1: Name | C1: Room | D1: Cargo (kg) | E1: Power when on (kW) | F1: Hours on per sol | G1: Average power (kW) | H1: Makes power (kW) | I1: O2 (kg/sol) | J1: CO2 (kg/sol) | K1: Water (L/sol) | L1: Food (kg/sol) | M1: Stores food (kg) | N1: Stores water (L) | O1: Stores O2 (kg) | P1: Stores energy (kWh) | Q1: Heats room (kW) | R1: Berths | S1: Research (per sol) | T1: Reference qty | U1: Notes / real-world basis
A2: crew_bunk | B2: Crew Bunk | C2: living | D2: 80 | E2: 0.02 | F2: 6 | G2: =E2*F2/24 | H2: 0 | I2: 0 | J2: 0 | K2: 0 | L2: 0 | M2: 0 | N2: 0 | O2: 0 | P2: 0 | Q2: 0 | R2: 1 | S2: 0 | T2: 6 | U2: Bunk with a reading light. One berth.
A3: locker | B3: Personal Locker | C3: living | D3: 40 | E3: 0 | F3: 0 | G3: =E3*F3/24 | H3: 0 | I3: 0 | J3: 0 | K3: 0 | L3: 0 | M3: 0 | N3: 0 | O3: 0 | P3: 0 | Q3: 0 | R3: 0 | S3: 0 | T3: 6 | U3: Personal storage.
A4: common_table | B4: Common Table | C4: living | D4: 60 | E4: 0 | F4: 0 | G4: =E4*F4/24 | H4: 0 | I4: 0 | J4: 0 | K4: 0 | L4: 0 | M4: 0 | N4: 0 | O4: 0 | P4: 0 | Q4: 0 | R4: 0 | S4: 0 | T4: 1
A5: task_light | B5: Task Light | C5: living | D5: 5 | E5: 0.03 | F5: 6 | G5: =E5*F5/24 | H5: 0 | I5: 0 | J5: 0 | K5: 0 | L5: 0 | M5: 0 | N5: 0 | O5: 0 | P5: 0 | Q5: 0 | R5: 0 | S5: 0 | T5: 2 | U5: Lights only while switched on.
A6: privacy_divider | B6: Privacy Divider | C6: living | D6: 25 | E6: 0 | F6: 0 | G6: =E6*F6/24 | H6: 0 | I6: 0 | J6: 0 | K6: 0 | L6: 0 | M6: 0 | N6: 0 | O6: 0 | P6: 0 | Q6: 0 | R6: 0 | S6: 0 | T6: 0
A7: exercise_station | B7: Exercise Station | C7: living | D7: 120 | E7: 0.1 | F7: 2 | G7: =E7*F7/24 | H7: 0 | I7: 0 | J7: 0 | K7: 0 | L7: 0 | M7: 0 | N7: 0 | O7: 0 | P7: 0 | Q7: 0 | R7: 0 | S7: 0 | T7: 1 | U7: Keeps bones and muscles strong (crew health, later).
A8: science_workbench | B8: Science Workbench | C8: science | D8: 150 | E8: 0.5 | F8: 10 | G8: =E8*F8/24 | H8: 0 | I8: 0 | J8: 0 | K8: 0 | L8: 0 | M8: 0 | N8: 0 | O8: 0 | P8: 0 | Q8: 0 | R8: 0 | S8: 1 | T8: 2
A9: microscope_station | B9: Microscope Station | C9: science | D9: 40 | E9: 0.1 | F9: 6 | G9: =E9*F9/24 | H9: 0 | I9: 0 | J9: 0 | K9: 0 | L9: 0 | M9: 0 | N9: 0 | O9: 0 | P9: 0 | Q9: 0 | R9: 0 | S9: 0.5 | T9: 1
A10: sample_storage_cabinet | B10: Sample Storage Cabinet | C10: science | D10: 60 | E10: 0.05 | F10: 24 | G10: =E10*F10/24 | H10: 0 | I10: 0 | J10: 0 | K10: 0 | L10: 0 | M10: 0 | N10: 0 | O10: 0 | P10: 0 | Q10: 0 | R10: 0 | S10: 0 | T10: 1 | U10: Cooled sample store.
A11: grow_tray | B11: Grow Tray | C11: hydroponics | D11: 150 | E11: 0.6 | F11: 16 | G11: =E11*F11/24 | H11: 0 | I11: 0.07 | J11: -0.1 | K11: -0.5 | L11: 0.4 | M11: 0 | N11: 0 | O11: 0 | P11: 0 | Q11: 0 | R11: 0 | S11: 0 | T11: 10 | U11: LED grow lights 16 h a day. About 2 m2 of crops. Plants absorb a little CO2.
A12: seedling_station | B12: Seedling Station | C12: hydroponics | D12: 80 | E12: 0.2 | F12: 16 | G12: =E12*F12/24 | H12: 0 | I12: 0 | J12: 0 | K12: -0.1 | L12: 0 | M12: 0 | N12: 0 | O12: 0 | P12: 0 | Q12: 0 | R12: 0 | S12: 0 | T12: 1 | U12: Starts new plants (faster regrowth, later).
A13: nutrient_mixer | B13: Nutrient Mixer | C13: hydroponics | D13: 90 | E13: 0.2 | F13: 24 | G13: =E13*F13/24 | H13: 0 | I13: 0 | J13: 0 | K13: 0 | L13: 0 | M13: 0 | N13: 0 | O13: 0 | P13: 0 | Q13: 0 | R13: 0 | S13: 0 | T13: 1 | U13: Feeds up to 8 grow trays or planters in its room.
A14: harvest_cart | B14: Harvest Cart | C14: hydroponics | D14: 30 | E14: 0 | F14: 0 | G14: =E14*F14/24 | H14: 0 | I14: 0 | J14: 0 | K14: 0 | L14: 0 | M14: 0 | N14: 0 | O14: 0 | P14: 0 | Q14: 0 | R14: 0 | S14: 0 | T14: 1
A15: greenhouse_planter | B15: Large Planter | C15: hydroponics | D15: 200 | E15: 0.8 | F15: 16 | G15: =E15*F15/24 | H15: 0 | I15: 0.1 | J15: -0.15 | K15: -0.7 | L15: 0.6 | M15: 0 | N15: 0 | O15: 0 | P15: 0 | Q15: 0 | R15: 0 | S15: 0 | T15: 0 | U15: Larger crop bed.
A16: air_recycler | B16: Air Recycler | C16: life_support | D16: 250 | E16: 0.8 | F16: 24 | G16: =E16*F16/24 | H16: 0 | I16: 0 | J16: -5 | K16: 0 | L16: 0 | M16: 0 | N16: 0 | O16: 0 | P16: 0 | Q16: 0 | R16: 0 | S16: 0 | T16: 2 | U16: CO2 scrubber, like the ISS CDRA. Enough for 5 crew.
A17: oxygen_generator | B17: Oxygen Generator | C17: life_support | D17: 300 | E17: 1.5 | F17: 24 | G17: =E17*F17/24 | H17: 0 | I17: 3 | J17: 0 | K17: -3.4 | L17: 0 | M17: 0 | N17: 0 | O17: 0 | P17: 0 | Q17: 0 | R17: 0 | S17: 0 | T17: 2 | U17: NEW MODEL NEEDED. Splits water into oxygen (electrolysis), like the ISS OGA.
A18: water_reclaimer | B18: Water Reclaimer | C18: life_support | D18: 300 | E18: 0.6 | F18: 24 | G18: =E18*F18/24 | H18: 0 | I18: 0 | J18: 0 | K18: 0 | L18: 0 | M18: 0 | N18: 300 | O18: 0 | P18: 0 | Q18: 0 | R18: 0 | S18: 0 | T18: 0 | U18: Recovers used water (see Settings) up to 70 L a sol. Reference qty is set per site in Balance Check.
A19: oxygen_reserve_tank | B19: Oxygen Reserve | C19: life_support | D19: 150 | E19: 0 | F19: 0 | G19: =E19*F19/24 | H19: 0 | I19: 0 | J19: 0 | K19: 0 | L19: 0 | M19: 0 | N19: 0 | O19: 100 | P19: 0 | Q19: 0 | R19: 0 | S19: 0 | T19: 1 | U19: Filled on Earth: the oxygen inside counts as cargo too.
A20: thermal_control_unit | B20: Thermal Control Unit | C20: life_support | D20: 250 | E20: 0.3 | F20: 24 | G20: =E20*F20/24 | H20: 0 | I20: 0 | J20: 0 | K20: 0 | L20: 0 | M20: 0 | N20: 0 | O20: 0 | P20: 0 | Q20: 12 | R20: 0 | S20: 0 | T20: 1 | U20: Heat pump: moves up to 12 kW of heat into (or out of) rooms. Its pumping power is worked out in Balance Check.
A21: cargo_rack | B21: Cargo Rack | C21: storage | D21: 60 | E21: 0 | F21: 0 | G21: =E21*F21/24 | H21: 0 | I21: 0 | J21: 0 | K21: 0 | L21: 0 | M21: 500 | N21: 0 | O21: 0 | P21: 0 | Q21: 0 | R21: 0 | S21: 0 | T21: 1 | U21: Holds supplies brought from Earth.
A22: tool_bench | B22: Tool Bench | C22: storage | D22: 120 | E22: 0.3 | F22: 2 | G22: =E22*F22/24 | H22: 0 | I22: 0 | J22: 0 | K22: 0 | L22: 0 | M22: 0 | N22: 0 | O22: 0 | P22: 0 | Q22: 0 | R22: 0 | S22: 0 | T22: 1 | U22: Repairs (spare parts, later).
A23: rover_charger | B23: Rover Charger | C23: vehicle_bay | D23: 150 | E23: 3 | F23: 4 | G23: =E23*F23/24 | H23: 0 | I23: 0 | J23: 0 | K23: 0 | L23: 0 | M23: 0 | N23: 0 | O23: 0 | P23: 0 | Q23: 0 | R23: 0 | S23: 0 | T23: 0 | U23: Charges the rover's batteries.
A24: eva_tool_station | B24: EVA Tool Station | C24: vehicle_bay | D24: 100 | E24: 0 | F24: 0 | G24: =E24*F24/24 | H24: 0 | I24: 0 | J24: 0 | K24: 0 | L24: 0 | M24: 0 | N24: 0 | O24: 0 | P24: 0 | Q24: 0 | R24: 0 | S24: 0 | T24: 0
A25: suit_rack | B25: Suit Rack | C25: vehicle_bay | D25: 120 | E25: 0.2 | F25: 24 | G25: =E25*F25/24 | H25: 0 | I25: 0 | J25: 0 | K25: 0 | L25: 0 | M25: 0 | N25: 0 | O25: 0 | P25: 0 | Q25: 0 | R25: 0 | S25: 0 | T25: 1 | U25: Keeps suit batteries charged.
A26: corridor_light_strip | B26: Corridor Light Strip | C26: corridor | D26: 10 | E26: 0.02 | F26: 12 | G26: =E26*F26/24 | H26: 0 | I26: 0 | J26: 0 | K26: 0 | L26: 0 | M26: 0 | N26: 0 | O26: 0 | P26: 0 | Q26: 0 | R26: 0 | S26: 0 | T26: 4
A27: wayfinding_panel | B27: Wayfinding Panel | C27: corridor | D27: 10 | E27: 0.01 | F27: 24 | G27: =E27*F27/24 | H27: 0 | I27: 0 | J27: 0 | K27: 0 | L27: 0 | M27: 0 | N27: 0 | O27: 0 | P27: 0 | Q27: 0 | R27: 0 | S27: 0 | T27: 0
A28: utility_conduit | B28: Utility Conduit | C28: corridor | D28: 30 | E28: 0 | F28: 0 | G28: =E28*F28/24 | H28: 0 | I28: 0 | J28: 0 | K28: 0 | L28: 0 | M28: 0 | N28: 0 | O28: 0 | P28: 0 | Q28: 0 | R28: 0 | S28: 0 | T28: 0
A29: airlock_control_panel | B29: Airlock Control Panel | C29: airlock | D29: 40 | E29: 0.1 | F29: 24 | G29: =E29*F29/24 | H29: 0 | I29: 0 | J29: 0 | K29: 0 | L29: 0 | M29: 0 | N29: 0 | O29: 0 | P29: 0 | Q29: 0 | R29: 0 | S29: 0 | T29: 1
A30: suit_service_panel | B30: Suit Service Panel | C30: airlock | D30: 60 | E30: 0.3 | F30: 4 | G30: =E30*F30/24 | H30: 0 | I30: 0 | J30: 0 | K30: 0 | L30: 0 | M30: 0 | N30: 0 | O30: 0 | P30: 0 | Q30: 0 | R30: 0 | S30: 0 | T30: 1
A31: dust_grate | B31: Dust Grate | C31: airlock | D31: 30 | E31: 0 | F31: 0 | G31: =E31*F31/24 | H31: 0 | I31: 0 | J31: 0 | K31: 0 | L31: 0 | M31: 0 | N31: 0 | O31: 0 | P31: 0 | Q31: 0 | R31: 0 | S31: 0 | T31: 1 | U31: Keeps dust out of the habitat.
A32: power_distribution_panel | B32: Power Distribution Cabinet | C32: engineering | D32: 100 | E32: 0.05 | F32: 24 | G32: =E32*F32/24 | H32: 0 | I32: 0 | J32: 0 | K32: 0 | L32: 0 | M32: 0 | N32: 0 | O32: 0 | P32: 0 | Q32: 0 | R32: 0 | S32: 0 | T32: 1
A33: battery_bank | B33: Battery Bank | C33: engineering | D33: 400 | E33: 0 | F33: 0 | G33: =E33*F33/24 | H33: 0 | I33: 0 | J33: 0 | K33: 0 | L33: 0 | M33: 0 | N33: 0 | O33: 0 | P33: =Settings!$B$22 | Q33: 0 | R33: 0 | S33: 0 | T33: 0 | U33: Storage size is in Settings. Reference qty is set per site in Balance Check.
A34: galley_counter | B34: Galley Counter | C34: galley | D34: 150 | E34: 1.5 | F34: 3 | G34: =E34*F34/24 | H34: 0 | I34: 0 | J34: 0 | K34: 0 | L34: 0 | M34: 0 | N34: 0 | O34: 0 | P34: 0 | Q34: 0 | R34: 0 | S34: 0 | T34: 1 | U34: Food warmer and sink, used at mealtimes.
A35: pantry_cabinet | B35: Pantry Cabinet | C35: galley | D35: 90 | E35: 0 | F35: 0 | G35: =E35*F35/24 | H35: 0 | I35: 0 | J35: 0 | K35: 0 | L35: 0 | M35: 300 | N35: 0 | O35: 0 | P35: 0 | Q35: 0 | R35: 0 | S35: 0 | T35: 2
A36: potable_water_dispenser | B36: Water Dispenser | C36: galley | D36: 30 | E36: 0.05 | F36: 24 | G36: =E36*F36/24 | H36: 0 | I36: 0 | J36: 0 | K36: 0 | L36: 0 | M36: 0 | N36: 20 | O36: 0 | P36: 0 | Q36: 0 | R36: 0 | S36: 0 | T36: 1
A37: integrated_mess_booth | B37: Mess Booth | C37: living | D37: 120 | E37: 0 | F37: 0 | G37: =E37*F37/24 | H37: 0 | I37: 0 | J37: 0 | K37: 0 | L37: 0 | M37: 0 | N37: 0 | O37: 0 | P37: 0 | Q37: 0 | R37: 0 | S37: 0 | T37: 1
A38: hygiene_shower | B38: Low-Water Wash Station | C38: hygiene | D38: 120 | E38: 0.5 | F38: 2 | G38: =E38*F38/24 | H38: 0 | I38: 0 | J38: 0 | K38: 0 | L38: 0 | M38: 0 | N38: 0 | O38: 0 | P38: 0 | Q38: 0 | R38: 0 | S38: 0 | T38: 1 | U38: Heats washing water. Without one, crew use less water but health suffers (later).
A39: hygiene_toilet | B39: Vacuum Toilet | C39: hygiene | D39: 100 | E39: 0.1 | F39: 24 | G39: =E39*F39/24 | H39: 0 | I39: 0 | J39: 0 | K39: 0 | L39: 0 | M39: 0 | N39: 0 | O39: 0 | P39: 0 | Q39: 0 | R39: 0 | S39: 0 | T39: 2 | U39: Air-flow toilet; urine goes to the reclaimer.
A40: medical_cabinet | B40: Medical Supply Cabinet | C40: medical | D40: 80 | E40: 0 | F40: 0 | G40: =E40*F40/24 | H40: 0 | I40: 0 | J40: 0 | K40: 0 | L40: 0 | M40: 0 | N40: 0 | O40: 0 | P40: 0 | Q40: 0 | R40: 0 | S40: 0 | T40: 1
...

Sheet Sites
A1: Setting | B1: Open Plains | C1: Canyon Ridge | D1: Crater Basin | E1: Ice Fields | F1: Notes
A2: Game id | B2: plains | C2: ridge | D2: crater | E2: ice
A3: Based on | B3: Elysium Planitia | C3: Valles Marineris floor | D3: Gale Crater lowlands | E3: Utopia Basin South
A4: Daytime temperature (C) | B4: -25 | C4: -22 | D4: -10 | E4: -45 | F4: Warmest part of the sol.
A5: Night temperature (C) | B5: -68 | C5: -62 | D5: -55 | E5: -82 | F5: Coldest, just before dawn.
A6: Average temperature (C) | B6: =(B4+B5)/2 | C6: =(C4+C5)/2 | D6: =(D4+D5)/2 | E6: =(E4+E5)/2 | F6: Worked out from the two above.
A7: Daylight hours | B7: 14 | C7: 13 | D7: 14.5 | E7: 12 | F7: Sunrise to sunset.
A8: Solar energy per array (kWh/sol) | B8: =8.575*Settings!$B$20 | C8: =6.402*Settings!$B$20 | D8: =7.89*Settings!$B$20 | E8: =4.437*Settings!$B$20 | F8: From the game's sun curve (height of the sun, cliffs and crater rims hiding it) for a south-facing array, times its peak output.
A9: Best ice richness (0-1) | B9: 0.32 | C9: 0.82 | D9: 0.5 | E9: 0.92 | F9: From the site map. Drill output = drill L/sol x richness.
A10: Dust storms per 100 sols | B10: 6 | C10: 8 | D10: 4 | E10: 5 | F10: How often a storm hits in Survival and Freedom (each comes with a forecast warning). Raised on 22 Oct so storms happen in a normal session. Tests can force one.
A11: Storm cuts solar by | B11: 0.7 | C11: 0.6 | D11: 0.5 | E11: 0.6 | F11: Share of solar output lost during a storm.
A12: Storm length (sols) | B12: 2 | C12: 1.5 | D12: 1.5 | E12: 2.5 | F12: Shortened on 22 Oct (a sol is about 20 minutes of play). Mission storms set their own length.
A13: Landing cargo bonus | B13: 0 | C13: 0.08 | D13: 0 | E13: 0.08 | F13: Low sites (deep canyon, Utopia basin) have thicker air for parachutes, so landers carry more.
A14: Build area limit (m) | B14: 90 | C14: 60 | D14: 48 | E14: 72 | F14: From the site map.

Sheet Balance Check
A1: Reference 6-crew habitat on each site
A2: Blue rows are the design choices for each site. Everything else is worked out. 'SHORT' means the design does not work there.
A4: Site | B4: =Sites!B2 | C4: =Sites!C2 | D4: =Sites!D2 | E4: =Sites!E2
A5: Design choices (per site)
A6: Solar arrays | B6: 6 | C6: 8 | D6: 6 | E6: 1
A7: Reactors | B7: 0 | C7: 0 | D7: 0 | E7: 2
A8: Battery banks | B8: 6 | C8: 7 | D8: 6 | E8: 2
A9: Ice drills | B9: 1 | C9: 1 | D9: 1 | E9: 1
A10: Water reclaimers | B10: 1 | C10: 0 | D10: 1 | E10: 0
A11: Thermal control units | B11: 2 | C11: 1 | D11: 1 | E11: 2
A13: Cargo
A14: Room cells | B14: =Rooms!$G$16 | C14: =Rooms!$G$16 | D14: =Rooms!$G$16 | E14: =Rooms!$G$16
A15: Rooms | B15: =Rooms!$H$16 | C15: =Rooms!$H$16 | D15: =Rooms!$H$16 | E15: =Rooms!$H$16
A16: Equipment (reference qty) | B16: =SUMPRODUCT(Equipment!$T$2:$T$68,Equipment!$D$2:$D$68) | C16: =SUMPRODUCT(Equipment!$T$2:$T$68,Equipment!$D$2:$D$68) | D16: =SUMPRODUCT(Equipment!$T$2:$T$68,Equipment!$D$2:$D$68) | E16: =SUMPRODUCT(Equipment!$T$2:$T$68,Equipment!$D$2:$D$68) | F16: Everything on the Equipment sheet with a Reference qty.
A17: Power, water and heating kit | B17: =B6*Equipment!$D$55+B7*Equipment!$D$56+B8*Equipment!$D$33+B9*Equipment!$D$57+B10*Equipment!$D$18+(B11-1)*Equipment!$D$20 | C17: =C6*Equipment!$D$55+C7*Equipment!$D$56+C8*Equipment!$D$33+C9*Equipment!$D$57+C10*Equipment!$D$18+(C11-1)*Equipment!$D$20 | D17: =D6*Equipment!$D$55+D7*Equipment!$D$56+D8*Equipment!$D$33+D9*Equipment!$D$57+D10*Equipment!$D$18+(D11-1)*Equipment!$D$20 | E17: =E6*Equipment!$D$55+E7*Equipment!$D$56+E8*Equipment!$D$33+E9*Equipment!$D$57+E10*Equipment!$D$18+(E11-1)*Equipment!$D$20 | F17: The chosen arrays, reactors, batteries, drills and reclaimers (one thermal unit is already in the reference qty).
A18: Food eaten over the mission (kg) | B18: =Settings!$B$2*Settings!$B$9*Settings!$B$3 | C18: =Settings!$B$2*Settings!$B$9*Settings!$B$3 | D18: =Settings!$B$2*Settings!$B$9*Settings!$B$3 | E18: =Settings!$B$2*Settings!$B$9*Settings!$B$3
A19: Food grown over the mission (kg) | B19: =SUMPRODUCT(Equipment!$T$2:$T$68,Equipment!$L$2:$L$68)*Settings!$B$3 | C19: =SUMPRODUCT(Equipment!$T$2:$T$68,Equipment!$L$2:$L$68)*Settings!$B$3 | D19: =SUMPRODUCT(Equipment!$T$2:$T$68,Equipment!$L$2:$L$68)*Settings!$B$3 | E19: =SUMPRODUCT(Equipment!$T$2:$T$68,Equipment!$L$2:$L$68)*Settings!$B$3
A20: Food to bring from Earth | B20: =MAX(0,B18-B19) | C20: =MAX(0,C18-C19) | D20: =MAX(0,D18-D19) | E20: =MAX(0,E18-E19)
A21: Oxygen in reserve tanks | B21: =SUMPRODUCT(Equipment!$T$2:$T$68,Equipment!$O$2:$O$68) | C21: =SUMPRODUCT(Equipment!$T$2:$T$68,Equipment!$O$2:$O$68) | D21: =SUMPRODUCT(Equipment!$T$2:$T$68,Equipment!$O$2:$O$68) | E21: =SUMPRODUCT(Equipment!$T$2:$T$68,Equipment!$O$2:$O$68)
A22: Starting water | B22: =Equipment!$N$18*B10+100 | C22: =Equipment!$N$18*C10+100 | D22: =Equipment!$N$18*D10+100 | E22: =Equipment!$N$18*E10+100 | F22: Tanks filled on Earth (1 L = 1 kg) plus 100 L in pipes.
A23: Total cargo | B23: =B15+B16+B17+B20+B21+B22 | C23: =C15+C16+C17+C20+C21+C22 | D23: =D15+D16+D17+D20+D21+D22 | E23: =E15+E16+E17+E20+E21+E22
A24: Cargo budget (with landing bonus) | B24: =Settings!$B$4*(1+Sites!B13) | C24: =Settings!$B$4*(1+Sites!C13) | D24: =Settings!$B$4*(1+Sites!D13) | E24: =Settings!$B$4*(1+Sites!E13)
A25: Spare cargo | B25: =(B24-B23)/B24 | C25: =(C24-C23)/C24 | D25: =(D24-D23)/D24 | E25: =(E24-E23)/E24 | F25: Aim for roughly 5-20% so students have choices but must make trade-offs.
A26: Cargo | B26: =IF(B23<=B24,"OK","SHORT") | C26: =IF(C23<=C24,"OK","SHORT") | D26: =IF(D23<=D24,"OK","SHORT") | E26: =IF(E23<=E24,"OK","SHORT")
A28: Power (one sol)
A29: Average indoor load (kW) | B29: =SUMPRODUCT(Equipment!$T$2:$T$68,Equipment!$G$2:$G$68)+SUMPRODUCT(Rooms!$D$2:$D$15,Rooms!$G$2:$G$15)+SUMPRODUCT(Rooms!$E$2:$E$15,Rooms!$G$2:$G$15)*Settings!$B$25/24+B10*Equipment!$G$18 | C29: =SUMPRODUCT(Equipment!$T$2:$T$68,Equipment!$G$2:$G$68)+SUMPRODUCT(Rooms!$D$2:$D$15,Rooms!$G$2:$G$15)+SUMPRODUCT(Rooms!$E$2:$E$15,Rooms!$G$2:$G$15)*Settings!$B$25/24+C10*Equipment!$G$18 | D29: =SUMPRODUCT(Equipment!$T$2:$T$68,Equipment!$G$2:$G$68)+SUMPRODUCT(Rooms!$D$2:$D$15,Rooms!$G$2:$G$15)+SUMPRODUCT(Rooms!$E$2:$E$15,Rooms!$G$2:$G$15)*Settings!$B$25/24+D10*Equipment!$G$18 | E29: =SUMPRODUCT(Equipment!$T$2:$T$68,Equipment!$G$2:$G$68)+SUMPRODUCT(Rooms!$D$2:$D$15,Rooms!$G$2:$G$15)+SUMPRODUCT(Rooms!$E$2:$E$15,Rooms!$G$2:$G$15)*Settings!$B$25/24+E10*Equipment!$G$18 | F29: Machines at their average, plus ventilation and lights in every cell.
A30: Ice drills (kW) | B30: =B9*Equipment!$G$57 | C30: =C9*Equipment!$G$57 | D30: =D9*Equipment!$G$57 | E30: =E9*Equipment!$G$57 | F30: Their heat is lost outside.
A31: Heat lost through the hull, average (kW) | B31: =B14*Settings!$B$12*Settings!$B$11*(Settings!$B$15-Sites!B6)/1000 | C31: =C14*Settings!$B$12*Settings!$B$11*(Settings!$B$15-Sites!C6)/1000 | D31: =D14*Settings!$B$12*Settings!$B$11*(Settings!$B$15-Sites!D6)/1000 | E31: =E14*Settings!$B$12*Settings!$B$11*(Settings!$B$15-Sites!E6)/1000
A32: Heat lost at night (kW) | B32: =B14*Settings!$B$12*Settings!$B$11*(Settings!$B$15-Sites!B5)/1000 | C32: =C14*Settings!$B$12*Settings!$B$11*(Settings!$B$15-Sites!C5)/1000 | D32: =D14*Settings!$B$12*Settings!$B$11*(Settings!$B$15-Sites!D5)/1000 | E32: =E14*Settings!$B$12*Settings!$B$11*(Settings!$B$15-Sites!E5)/1000
A33: Heat from people and machines (kW) | B33: =B29+Settings!$B$2*Settings!$B$10 | C33: =C29+Settings!$B$2*Settings!$B$10 | D33: =D29+Settings!$B$2*Settings!$B$10 | E33: =E29+Settings!$B$2*Settings!$B$10 | F33: Almost all electricity used indoors ends up as heat.
A34: Heating power needed, average (kW) | B34: =MAX(0,B31-B33)/Settings!$B$16 | C34: =MAX(0,C31-C33)/Settings!$B$16 | D34: =MAX(0,D31-D33)/Settings!$B$16 | E34: =MAX(0,E31-E33)/Settings!$B$16 | F34: Electricity for the thermal control unit to make up the rest.
A35: Heating power needed at night (kW) | B35: =MAX(0,B32-B33)/Settings!$B$16 | C35: =MAX(0,C32-C33)/Settings!$B$16 | D35: =MAX(0,D32-D33)/Settings!$B$16 | E35: =MAX(0,E32-E33)/Settings!$B$16
A36: Thermal units can move (kW of heat) | B36: =B11*Equipment!$Q$20 | C36: =C11*Equipment!$Q$20 | D36: =D11*Equipment!$Q$20 | E36: =E11*Equipment!$Q$20
A37: Heating capacity | B37: =IF(B36>=MAX(0,B32-B33),"OK","SHORT") | C37: =IF(C36>=MAX(0,C32-C33),"OK","SHORT") | D37: =IF(D36>=MAX(0,D32-D33),"OK","SHORT") | E37: =IF(E36>=MAX(0,E32-E33),"OK","SHORT") | F37: Enough thermal control units for the coldest night.
A38: Energy used per sol (kWh) | B38: =(B29+B30+B34)*24 | C38: =(C29+C30+C34)*24 | D38: =(D29+D30+D34)*24 | E38: =(E29+E30+E34)*24
A39: Energy made per sol (kWh) | B39: =B6*Sites!B8+B7*Settings!$B$21*24 | C39: =C6*Sites!C8+C7*Settings!$B$21*24 | D39: =D6*Sites!D8+D7*Settings!$B$21*24 | E39: =E6*Sites!E8+E7*Settings!$B$21*24
A40: Daily energy | B40: =IF(B39>=B38,"OK","SHORT") | C40: =IF(C39>=C38,"OK","SHORT") | D40: =IF(D39>=D38,"OK","SHORT") | E40: =IF(E39>=E38,"OK","SHORT")
A41: Night hours | B41: =24-Sites!B7 | C41: =24-Sites!C7 | D41: =24-Sites!D7 | E41: =24-Sites!E7
A42: Energy needed through the night (kWh) | B42: =(B29+B30+B35-B7*Settings!$B$21)*B41 | C42: =(C29+C30+C35-C7*Settings!$B$21)*C41 | D42: =(D29+D30+D35-D7*Settings!$B$21)*D41 | E42: =(E29+E30+E35-E7*Settings!$B$21)*E41 | F42: What the batteries must hold after the reactor's share.
A43: Battery storage (kWh) | B43: =B8*Settings!$B$22 | C43: =C8*Settings!$B$22 | D43: =D8*Settings!$B$22 | E43: =E8*Settings!$B$22
...
